Workbook

Sheet _instrucoes
A1: TEMPLATE PADRÃO GT — BALANÇO PATRIMONIAL + DRE
A2: Estrutura sintética para Valuation. Baseada nos agrupadores oficiais L100A / L300A (ECF).
A4: COMO O PROGRAMA DEVE ALIMENTAR O TEMPLATE
A5: 1. Copie este arquivo antes de escrever qualquer coisa.
A6: 2. Escreva os dados extraídos APENAS na aba oculta '_dados_padronizados'.
A7: 3. Cada linha: código ECF do cliente + descrição + valores por ano.
A8: 4. Substitua '[NOME DO CLIENTE]' na célula B4 de BP_GT e DRE_GT.
A9: 5. Salve como novo arquivo. As fórmulas do template resolvem tudo.
A11: COMO AS FÓRMULAS FUNCIONAM
A12: As contas analíticas usam SUMIFS com WILDCARD sobre a coluna A de _dados_padronizados.
A13: Uma linha como 'Contas a receber de clientes' (código 1.01.02.02) agrega TUDO que
A14: começa com '1.01.02.02' — incluindo 1.01.02.02.01, .02, .03, etc.
... A31: PROJETO BP — Fernando Lisboa | GT Valuation

Sheet BP_GT
N1: Utilizar apenas se for um PPA
B4: [NOME DO CLIENTE]
B6: Em milhares de reais
B7: Balanço Patrimonial | C7: Código ECF | D7: 2021 | E7: 2022 | F7: 2023 | G7: 2024 | H7: 2025 | I7: Ajuste pro-forma | J7: Ajustado | L7: Classificação - GT | N7: Ajuste a Valor Justo | O7: Saldo a Valor Justo | Q7: Metodologia de Avaliação | S7: Para Copiar e Colar
B8: ATIVO CIRCULANTE
B9: Caixa e equivalentes de caixa | C9: 1.01.01 | D9: =IFERROR(SUMIFS(_dados_padronizados!C:C,_dados_padronizados!$A:$A,$C9&"*"),0) | E9: =IFERROR(SUMIFS(_dados_padronizados!D:D,_dados_padronizados!$A:$A,$C9&"*"),0) | F9: =IFERROR(SUMIFS(_dados_padronizados!E:E,_dados_padronizados!$A:$A,$C9&"*"),0) | G9: =IFERROR(SUMIFS(_dados_padronizados!F:F,_dados_padronizados!$A:$A,$C9&"*"),0) | H9: =IFERROR(SUMIFS(_dados_padronizados!G:G,_dados_padronizados!$A:$A,$C9&"*"),0) | J9: =H9+I9 | L9: Caixa / Dívida | O9: =J9+N9 | S9: Caixa / Dívida
B10: Contas a receber de clientes | C10: 1.01.02.02 | D10: =IFERROR(SUMIFS(_dados_padronizados!C:C,_dados_padronizados!$A:$A,$C10&"*"),0) | E10: =IFERROR(SUMIFS(_dados_padronizados!D:D,_dados_padronizados!$A:$A,$C10&"*"),0) | F10: =IFERROR(SUMIFS(_dados_padronizados!E:E,_dados_padronizados!$A:$A,$C10&"*"),0) | G10: =IFERROR(SUMIFS(_dados_padronizados!F:F,_dados_padronizados!$A:$A,$C10&"*"),0) | H10: =IFERROR(SUMIFS(_dados_padronizados!G:G,_dados_padronizados!$A:$A,$C10&"*"),0) | J10: =H10+I10 | L10: Capital de Giro | O10: =J10+N10 | S10: Capital de Giro
B11: Estoques | C11: 1.01.03 | D11: =IFERROR(SUMIFS(_dados_padronizados!C:C,_dados_padronizados!$A:$A,$C11&"*"),0) | E11: =IFERROR(SUMIFS(_dados_padronizados!D:D,_dados_padronizados!$A:$A,$C11&"*"),0) | F11: =IFERROR(SUMIFS(_dados_padronizados!E:E,_dados_padronizados!$A:$A,$C11&"*"),0) | G11: =IFERROR(SUMIFS(_dados_padronizados!F:F,_dados_padronizados!$A:$A,$C11&"*"),0) | H11: =IFERROR(SUMIFS(_dados_padronizados!G:G,_dados_padronizados!$A:$A,$C11&"*"),0) | J11: =H11+I11 | L11: Capital de Giro | O11: =J11+N11 | S11: Capital de Giro
B12: Tributos a recuperar | C12: 1.01.02.03 | D12: =IFERROR(SUMIFS(_dados_padronizados!C:C,_dados_padronizados!$A:$A,$C12&"*"),0) | E12: =IFERROR(SUMIFS(_dados_padronizados!D:D,_dados_padronizados!$A:$A,$C12&"*"),0) | F12: =IFERROR(SUMIFS(_dados_padronizados!E:E,_dados_padronizados!$A:$A,$C12&"*"),0) | G12: =IFERROR(SUMIFS(_dados_padronizados!F:F,_dados_padronizados!$A:$A,$C12&"*"),0) | H12: =IFERROR(SUMIFS(_dados_padronizados!G:G,_dados_padronizados!$A:$A,$C12&"*"),0) | J12: =H12+I12 | L12: Capital de Giro | O12: =J12+N12 | S12: Capital de Giro
B13: Adiantamentos e despesas antecipadas | C13: 1.01.02.01 | D13: =IFERROR(SUMIFS(_dados_padronizados!C:C,_dados_padronizados!$A:$A,$C13&"*"),0) | E13: =IFERROR(SUMIFS(_dados_padronizados!D:D,_dados_padronizados!$A:$A,$C13&"*"),0) | F13: =IFERROR(SUMIFS(_dados_padronizados!E:E,_dados_padronizados!$A:$A,$C13&"*"),0) | G13: =IFERROR(SUMIFS(_dados_padronizados!F:F,_dados_padronizados!$A:$A,$C13&"*"),0) | H13: =IFERROR(SUMIFS(_dados_padronizados!G:G,_dados_padronizados!$A:$A,$C13&"*"),0) | J13: =H13+I13 | L13: Capital de Giro | O13: =J13+N13 | S13: Capital de Giro
B14: Outros ativos circulantes | C14: 1.01.02.09 | D14: =IFERROR(SUMIFS(_dados_padronizados!C:C,_dados_padronizados!$A:$A,$C14&"*"),0) | E14: =IFERROR(SUMIFS(_dados_padronizados!D:D,_dados_padronizados!$A:$A,$C14&"*"),0) | F14: =IFERROR(SUMIFS(_dados_padronizados!E:E,_dados_padronizados!$A:$A,$C14&"*"),0) | G14: =IFERROR(SUMIFS(_dados_padronizados!F:F,_dados_padronizados!$A:$A,$C14&"*"),0) | H14: =IFERROR(SUMIFS(_dados_padronizados!G:G,_dados_padronizados!$A:$A,$C14&"*"),0) | J14: =H14+I14 | L14: Ativo / Passivo não Op. | O14: =J14+N14 | S14: Ativo / Passivo não Op.
B15: Total do Ativo Circulante | D15: =SUM(D9:D14) | E15: =SUM(E9:E14) | F15: =SUM(F9:F14) | G15: =SUM(G9:G14) | H15: =SUM(H9:H14) | I15: =SUM(I9:I14) | J15: =H15+I15 | N15: =SUM(N9:N14) | O15: =J15+N15
B17: ATIVO NÃO CIRCULANTE
B18: Contas a receber de longo prazo | C18: 1.02.01.01 | D18: =IFERROR(SUMIFS(_dados_padronizados!C:C,_dados_padronizados!$A:$A,$C18&"*"),0) | E18: =IFERROR(SUMIFS(_dados_padronizados!D:D,_dados_padronizados!$A:$A,$C18&"*"),0) | F18: =IFERROR(SUMIFS(_dados_padronizados!E:E,_dados_padronizados!$A:$A,$C18&"*"),0) | G18: =IFERROR(SUMIFS(_dados_padronizados!F:F,_dados_padronizados!$A:$A,$C18&"*"),0) | H18: =IFERROR(SUMIFS(_dados_padronizados!G:G,_dados_padronizados!$A:$A,$C18&"*"),0) | J18: =H18+I18 | L18: Capital de Giro | O18: =J18+N18 | Q18: Mercado | S18: Capital de Giro
B19: Tributos e impostos diferidos | C19: 1.02.01.05 | D19: =IFERROR(SUMIFS(_dados_padronizados!C:C,_dados_padronizados!$A:$A,$C19&"*"),0) | E19: =IFERROR(SUMIFS(_dados_padronizados!D:D,_dados_padronizados!$A:$A,$C19&"*"),0) | F19: =IFERROR(SUMIFS(_dados_padronizados!E:E,_dados_padronizados!$A:$A,$C19&"*"),0) | G19: =IFERROR(SUMIFS(_dados_padronizados!F:F,_dados_padronizados!$A:$A,$C19&"*"),0) | H19: =IFERROR(SUMIFS(_dados_padronizados!G:G,_dados_padronizados!$A:$A,$C19&"*"),0) | J19: =H19+I19 | L19: Ativo / Passivo não Op. | O19: =J19+N19 | Q19: Mercado | S19: Ativo / Passivo não Op.
B20: Investimentos | C20: 1.02.02 | D20: =IFERROR(SUMIFS(_dados_padronizados!C:C,_dados_padronizados!$A:$A,$C20&"*"),0) | E20: =IFERROR(SUMIFS(_dados_padronizados!D:D,_dados_padronizados!$A:$A,$C20&"*"),0) | F20: =IFERROR(SUMIFS(_dados_padronizados!E:E,_dados_padronizados!$A:$A,$C20&"*"),0) | G20: =IFERROR(SUMIFS(_dados_padronizados!F:F,_dados_padronizados!$A:$A,$C20&"*"),0) | H20: =IFERROR(SUMIFS(_dados_padronizados!G:G,_dados_padronizados!$A:$A,$C20&"*"),0) | J20: =H20+I20 | L20: Ativo / Passivo não Op. | O20: =J20+N20 | Q20: Mercado | S20: Ativo / Passivo não Op.
B21: Imobilizado | C21: 1.02.03 | D21: =IFERROR(SUMIFS(_dados_padronizados!C:C,_dados_padronizados!$A:$A,$C21&"*"),0) | E21: =IFERROR(SUMIFS(_dados_padronizados!D:D,_dados_padronizados!$A:$A,$C21&"*"),0) | F21: =IFERROR(SUMIFS(_dados_padronizados!E:E,_dados_padronizados!$A:$A,$C21&"*"),0) | G21: =IFERROR(SUMIFS(_dados_padronizados!F:F,_dados_padronizados!$A:$A,$C21&"*"),0) | H21: =IFERROR(SUMIFS(_dados_padronizados!G:G,_dados_padronizados!$A:$A,$C21&"*"),0) | J21: =H21+I21 | L21: Fluxo de Caixa | O21: =J21+N21 | Q21: Mercado - Detalhado no Anexo | S21: Fluxo de Caixa
B22: Intangível | C22: 1.02.05 | D22: =IFERROR(SUMIFS(_dados_padronizados!C:C,_dados_padronizados!$A:$A,$C22&"*"),0) | E22: =IFERROR(SUMIFS(_dados_padronizados!D:D,_dados_padronizados!$A:$A,$C22&"*"),0) | F22: =IFERROR(SUMIFS(_dados_padronizados!E:E,_dados_padronizados!$A:$A,$C22&"*"),0) | G22: =IFERROR(SUMIFS(_dados_padronizados!F:F,_dados_padronizados!$A:$A,$C22&"*"),0) | H22: =IFERROR(SUMIFS(_dados_padronizados!G:G,_dados_padronizados!$A:$A,$C22&"*"),0) | J22: =H22+I22 | L22: Fluxo de Caixa | O22: =J22+N22 | Q22: Renda - MPEEM | S22: Fluxo de Caixa
B23: Outros ativos não circulantes | C23: 1.02.01.15 | D23: =IFERROR(SUMIFS(_dados_padronizados!C:C,_dados_padronizados!$A:$A,$C23&"*"),0) | E23: =IFERROR(SUMIFS(_dados_padronizados!D:D,_dados_padronizados!$A:$A,$C23&"*"),0) | F23: =IFERROR(SUMIFS(_dados_padronizados!E:E,_dados_padronizados!$A:$A,$C23&"*"),0) | G23: =IFERROR(SUMIFS(_dados_padronizados!F:F,_dados_padronizados!$A:$A,$C23&"*"),0) | H23: =IFERROR(SUMIFS(_dados_padronizados!G:G,_dados_padronizados!$A:$A,$C23&"*"),0) | J23: =H23+I23 | L23: Ativo / Passivo não Op. | O23: =J23+N23 | Q23: Mercado | S23: Ativo / Passivo não Op.
B24: Total do Ativo Não Circulante | D24: =SUM(D18:D23) | E24: =SUM(E18:E23) | F24: =SUM(F18:F23) | G24: =SUM(G18:G23) | H24: =SUM(H18:H23) | I24: =SUM(I18:I23) | J24: =H24+I24 | N24: =SUM(N18:N23) | O24: =J24+N24
B26: ATIVO TOTAL | D26: =D15+D24 | E26: =E15+E24 | F26: =F15+F24 | G26: =G15+G24 | H26: =H15+H24 | I26: =I15+I24 | J26: =H26+I26 | N26: =N15+N24 | O26: =J26+N26
B28: PASSIVO CIRCULANTE
B29: Fornecedores | C29: 2.01.01.03 | D29: =IFERROR(SUMIFS(_dados_padronizados!C:C,_dados_padronizados!$A:$A,$C29&"*"),0) | E29: =IFERROR(SUMIFS(_dados_padronizados!D:D,_dados_padronizados!$A:$A,$C29&"*"),0) | F29: =IFERROR(SUMIFS(_dados_padronizados!E:E,_dados_padronizados!$A:$A,$C29&"*"),0) | G29: =IFERROR(SUMIFS(_dados_padronizados!F:F,_dados_padronizados!$A:$A,$C29&"*"),0) | H29: =IFERROR(SUMIFS(_dados_padronizados!G:G,_dados_padronizados!$A:$A,$C29&"*"),0) | J29: =H29+I29 | L29: Capital de Giro | O29: =J29+N29 | S29: Capital de Giro
B30: Empréstimos e financiamentos - CP | C30: 2.01.01.07 | D30: =IFERROR(SUMIFS(_dados_padronizados!C:C,_dados_padronizados!$A:$A,$C30&"*"),0) | E30: =IFERROR(SUMIFS(_dados_padronizados!D:D,_dados_padronizados!$A:$A,$C30&"*"),0) | F30: =IFERROR(SUMIFS(_dados_padronizados!E:E,_dados_padronizados!$A:$A,$C30&"*"),0) | G30: =IFERROR(SUMIFS(_dados_padronizados!F:F,_dados_padronizados!$A:$A,$C30&"*"),0) | H30: =IFERROR(SUMIFS(_dados_padronizados!G:G,_dados_padronizados!$A:$A,$C30&"*"),0) | J30: =H30+I30 | L30: Caixa / Dívida | O30: =J30+N30 | S30: Caixa / Dívida
B31: Obrigações trabalhistas e sociais | C31: 2.01.01.01 | D31: =IFERROR(SUMIFS(_dados_padronizados!C:C,_dados_padronizados!$A:$A,$C31&"*"),0) | E31: =IFERROR(SUMIFS(_dados_padronizados!D:D,_dados_padronizados!$A:$A,$C31&"*"),0) | F31: =IFERROR(SUMIFS(_dados_padronizados!E:E,_dados_padronizados!$A:$A,$C31&"*"),0) | G31: =IFERROR(SUMIFS(_dados_padronizados!F:F,_dados_padronizados!$A:$A,$C31&"*"),0) | H31: =IFERROR(SUMIFS(_dados_padronizados!G:G,_dados_padronizados!$A:$A,$C31&"*"),0) | J31: =H31+I31 | L31: Capital de Giro | O31: =J31+N31 | S31: Capital de Giro
B32: Obrigações tributárias | C32: 2.01.01.09 | D32: =IFERROR(SUMIFS(_dados_padronizados!C:C,_dados_padronizados!$A:$A,$C32&"*"),0) | E32: =IFERROR(SUMIFS(_dados_padronizados!D:D,_dados_padronizados!$A:$A,$C32&"*"),0) | F32: =IFERROR(SUMIFS(_dados_padronizados!E:E,_dados_padronizados!$A:$A,$C32&"*"),0) | G32: =IFERROR(SUMIFS(_dados_padronizados!F:F,_dados_padronizados!$A:$A,$C32&"*"),0) | H32: =IFERROR(SUMIFS(_dados_padronizados!G:G,_dados_padronizados!$A:$A,$C32&"*"),0) | J32: =H32+I32 | L32: Capital de Giro | O32: =J32+N32 | S32: Capital de Giro
B33: Contas a pagar e outras obrigações | C33: 2.01.01.05 | D33: =IFERROR(SUMIFS(_dados_padronizados!C:C,_dados_padronizados!$A:$A,$C33&"*"),0) | E33: =IFERROR(SUMIFS(_dados_padronizados!D:D,_dados_padronizados!$A:$A,$C33&"*"),0) | F33: =IFERROR(SUMIFS(_dados_padronizados!E:E,_dados_padronizados!$A:$A,$C33&"*"),0) | G33: =IFERROR(SUMIFS(_dados_padronizados!F:F,_dados_padronizados!$A:$A,$C33&"*"),0) | H33: =IFERROR(SUMIFS(_dados_padronizados!G:G,_dados_padronizados!$A:$A,$C33&"*"),0) | J33: =H33+I33 | L33: Capital de Giro | O33: =J33+N33 | S33: Capital de Giro
B34: Provisões - CP | C34: 2.01.01.15 | D34: =IFERROR(SUMIFS(_dados_padronizados!C:C,_dados_padronizados!$A:$A,$C34&"*"),0) | E34: =IFERROR(SUMIFS(_dados_padronizados!D:D,_dados_padronizados!$A:$A,$C34&"*"),0) | F34: =IFERROR(SUMIFS(_dados_padronizados!E:E,_dados_padronizados!$A:$A,$C34&"*"),0) | G34: =IFERROR(SUMIFS(_dados_padronizados!F:F,_dados_padronizados!$A:$A,$C34&"*"),0) | H34: =IFERROR(SUMIFS(_dados_padronizados!G:G,_dados_padronizados!$A:$A,$C34&"*"),0) | J34: =H34+I34 | L34: Ativo / Passivo não Op. | O34: =J34+N34 | S34: Ativo / Passivo não Op.
B35: Total do Passivo Circulante | D35: =SUM(D29:D34) | E35: =SUM(E29:E34) | F35: =SUM(F29:F34) | G35: =SUM(G29:G34) | H35: =SUM(H29:H34) | I35: =SUM(I29:I34) | J35: =H35+I35 | N35: =SUM(N29:N34) | O35: =J35+N35
B37: PASSIVO NÃO CIRCULANTE
B38: Empréstimos e financiamentos - LP | C38: 2.02.01.01 | D38: =IFERROR(SUMIFS(_dados_padronizados!C:C,_dados_padronizados!$A:$A,$C38&"*"),0) | E38: =IFERROR(SUMIFS(_dados_padronizados!D:D,_dados_padronizados!$A:$A,$C38&"*"),0) | F38: =IFERROR(SUMIFS(_dados_padronizados!E:E,_dados_padronizados!$A:$A,$C38&"*"),0) | G38: =IFERROR(SUMIFS(_dados_padronizados!F:F,_dados_padronizados!$A:$A,$C38&"*"),0) | H38: =IFERROR(SUMIFS(_dados_padronizados!G:G,_dados_padronizados!$A:$A,$C38&"*"),0) | J38: =H38+I38 | L38: Caixa / Dívida | O38: =J38+N38 | S38: Caixa / Dívida
B39: Tributos e impostos diferidos | C39: 2.02.01.05 | D39: =IFERROR(SUMIFS(_dados_padronizados!C:C,_dados_padronizados!$A:$A,$C39&"*"),0) | E39: =IFERROR(SUMIFS(_dados_padronizados!D:D,_dados_padronizados!$A:$A,$C39&"*"),0) | F39: =IFERROR(SUMIFS(_dados_padronizados!E:E,_dados_padronizados!$A:$A,$C39&"*"),0) | G39: =IFERROR(SUMIFS(_dados_padronizados!F:F,_dados_padronizados!$A:$A,$C39&"*"),0) | H39: =IFERROR(SUMIFS(_dados_padronizados!G:G,_dados_padronizados!$A:$A,$C39&"*"),0) | J39: =H39+I39 | L39: Ativo / Passivo não Op. | O39: =J39+N39 | S39: Ativo / Passivo não Op.
B40: Provisões - LP | C40: 2.02.01.09 | D40: =IFERROR(SUMIFS(_dados_padronizados!C:C,_dados_padronizados!$A:$A,$C40&"*"),0) | E40: =IFERROR(SUMIFS(_dados_padronizados!D:D,_dados_padronizados!$A:$A,$C40&"*"),0) | F40: =IFERROR(SUMIFS(_dados_padronizados!E:E,_dados_padronizados!$A:$A,$C40&"*"),0) | G40: =IFERROR(SUMIFS(_dados_padronizados!F:F,_dados_padronizados!$A:$A,$C40&"*"),0) | H40: =IFERROR(SUMIFS(_dados_padronizados!G:G,_dados_padronizados!$A:$A,$C40&"*"),0) | J40: =H40+I40 | L40: Ativo / Passivo não Op. | O40: =J40+N40 | S40: Ativo / Passivo não Op.
B41: Obrigações com partes relacionadas | C41: 2.02.01.11 | D41: =IFERROR(SUMIFS(_dados_padronizados!C:C,_dados_padronizados!$A:$A,$C41&"*"),0) | E41: =IFERROR(SUMIFS(_dados_padronizados!D:D,_dados_padronizados!$A:$A,$C41&"*"),0) | F41: =IFERROR(SUMIFS(_dados_padronizados!E:E,_dados_padronizados!$A:$A,$C41&"*"),0) | G41: =IFERROR(SUMIFS(_dados_padronizados!F:F,_dados_padronizados!$A:$A,$C41&"*"),0) | H41: =IFERROR(SUMIFS(_dados_padronizados!G:G,_dados_padronizados!$A:$A,$C41&"*"),0) | J41: =H41+I41 | L41: Ativo / Passivo não Op. | O41: =J41+N41 | S41: Ativo / Passivo não Op.
B42: Outras obrigações de longo prazo | C42: 2.02.01.21 | D42: =IFERROR(SUMIFS(_dados_padronizados!C:C,_dados_padronizados!$A:$A,$C42&"*"),0) | E42: =IFERROR(SUMIFS(_dados_padronizados!D:D,_dados_padronizados!$A:$A,$C42&"*"),0) | F42: =IFERROR(SUMIFS(_dados_padronizados!E:E,_dados_padronizados!$A:$A,$C42&"*"),0) | G42: =IFERROR(SUMIFS(_dados_padronizados!F:F,_dados_padronizados!$A:$A,$C42&"*"),0) | H42: =IFERROR(SUMIFS(_dados_padronizados!G:G,_dados_padronizados!$A:$A,$C42&"*"),0) | J42: =H42+I42 | L42: Ativo / Passivo não Op. | O42: =J42+N42 | S42: Ativo / Passivo não Op.
B43: Total do Passivo Não Circulante | D43: =SUM(D38:D42) | E43: =SUM(E38:E42) | F43: =SUM(F38:F42) | G43: =SUM(G38:G42) | H43: =SUM(H38:H42) | I43: =SUM(I38:I42) | J43: =H43+I43 | N43: =SUM(N38:N42) | O43: =J43+N43
B45: PATRIMÔNIO LÍQUIDO
B46: Capital social | C46: 2.03.01 | D46: =IFERROR(SUMIFS(_dados_padronizados!C:C,_dados_padronizados!$A:$A,$C46&"*"),0) | E46: =IFERROR(SUMIFS(_dados_padronizados!D:D,_dados_padronizados!$A:$A,$C46&"*"),0) | F46: =IFERROR(SUMIFS(_dados_padronizados!E:E,_dados_padronizados!$A:$A,$C46&"*"),0) | G46: =IFERROR(SUMIFS(_dados_padronizados!F:F,_dados_padronizados!$A:$A,$C46&"*"),0) | H46: =IFERROR(SUMIFS(_dados_padronizados!G:G,_dados_padronizados!$A:$A,$C46&"*"),0) | J46: =H46+I46 | O46: =J46+N46
B47: Reservas de capital e ajustes patrimoniais | C47: 2.03.02.01 | D47: =IFERROR(SUMIFS(_dados_padronizados!C:C,_dados_padronizados!$A:$A,$C47&"*"),0) | E47: =IFERROR(SUMIFS(_dados_padronizados!D:D,_dados_padronizados!$A:$A,$C47&"*"),0) | F47: =IFERROR(SUMIFS(_dados_padronizados!E:E,_dados_padronizados!$A:$A,$C47&"*"),0) | G47: =IFERROR(SUMIFS(_dados_padronizados!F:F,_dados_padronizados!$A:$A,$C47&"*"),0) | H47: =IFERROR(SUMIFS(_dados_padronizados!G:G,_dados_padronizados!$A:$A,$C47&"*"),0) | J47: =H47+I47 | O47: =J47+N47
B48: Reservas de lucros | C48: 2.03.02.03 | D48: =IFERROR(SUMIFS(_dados_padronizados!C:C,_dados_padronizados!$A:$A,$C48&"*"),0) | E48: =IFERROR(SUMIFS(_dados_padronizados!D:D,_dados_padronizados!$A:$A,$C48&"*"),0) | F48: =IFERROR(SUMIFS(_dados_padronizados!E:E,_dados_padronizados!$A:$A,$C48&"*"),0) | G48: =IFERROR(SUMIFS(_dados_padronizados!F:F,_dados_padronizados!$A:$A,$C48&"*"),0) | H48: =IFERROR(SUMIFS(_dados_padronizados!G:G,_dados_padronizados!$A:$A,$C48&"*"),0) | J48: =H48+I48 | O48: =J48+N48
...

Sheet DRE_GT
B4: [NOME DO CLIENTE]
B6: Em milhares de reais
B7: Demonstração do Resultado do Exercício (DRE) | C7: Código ECF | D7: 2021 | E7: 2022 | F7: 2023 | G7: 2024 | H7: 2025 | I7: Ajuste pro-forma | J7: Ajustado
B8: RECEITA BRUTA
B9: Receita bruta - venda de mercadorias e produtos | C9: 3.01.01.01.01.04|3.01.01.01.01.05 | D9: =IFERROR(SUMIFS(_dados_padronizados!C:C,_dados_padronizados!$A:$A,"3.01.01.01.01.04*")+SUMIFS(_dados_padronizados!C:C,_dados_padronizados!$A:$A,"3.01.01.01.01.05*"),0) | E9: =IFERROR(SUMIFS(_dados_padronizados!D:D,_dados_padronizados!$A:$A,"3.01.01.01.01.04*")+SUMIFS(_dados_padronizados!D:D,_dados_padronizados!$A:$A,"3.01.01.01.01.05*"),0) | F9: =IFERROR(SUMIFS(_dados_padronizados!E:E,_dados_padronizados!$A:$A,"3.01.01.01.01.04*")+SUMIFS(_dados_padronizados!E:E,_dados_padronizados!$A:$A,"3.01.01.01.01.05*"),0) | G9: =IFERROR(SUMIFS(_dados_padronizados!F:F,_dados_padronizados!$A:$A,"3.01.01.01.01.04*")+SUMIFS(_dados_padronizados!F:F,_dados_padronizados!$A:$A,"3.01.01.01.01.05*"),0) | H9: =IFERROR(SUMIFS(_dados_padronizados!G:G,_dados_padronizados!$A:$A,"3.01.01.01.01.04*")+SUMIFS(_dados_padronizados!G:G,_dados_padronizados!$A:$A,"3.01.01.01.01.05*"),0) | J9: =H9+I9
B10: Receita bruta - prestação de serviços | C10: 3.01.01.01.01.06 | D10: =IFERROR(SUMIFS(_dados_padronizados!C:C,_dados_padronizados!$A:$A,$C10&"*"),0) | E10: =IFERROR(SUMIFS(_dados_padronizados!D:D,_dados_padronizados!$A:$A,$C10&"*"),0) | F10: =IFERROR(SUMIFS(_dados_padronizados!E:E,_dados_padronizados!$A:$A,$C10&"*"),0) | G10: =IFERROR(SUMIFS(_dados_padronizados!F:F,_dados_padronizados!$A:$A,$C10&"*"),0) | H10: =IFERROR(SUMIFS(_dados_padronizados!G:G,_dados_padronizados!$A:$A,$C10&"*"),0) | J10: =H10+I10
B11: Receita bruta - outras | C11: 3.01.01.01.01.98|3.01.01.01.01.08|3.01.01.01.01.20 | D11: =IFERROR(SUMIFS(_dados_padronizados!C:C,_dados_padronizados!$A:$A,"3.01.01.01.01.98*")+SUMIFS(_dados_padronizados!C:C,_dados_padronizados!$A:$A,"3.01.01.01.01.08*")+SUMIFS(_dados_padronizados!C:C,_dados_padronizados!$A:$A,"3.01.01.01.01.20*"),0) | E11: =IFERROR(SUMIFS(_dados_padronizados!D:D,_dados_padronizados!$A:$A,"3.01.01.01.01.98*")+SUMIFS(_dados_padronizados!D:D,_dados_padronizados!$A:$A,"3.01.01.01.01.08*")+SUMIFS(_dados_padronizados!D:D,_dados_padronizados!$A:$A,"3.01.01.01.01.20*"),0) | F11: =IFERROR(SUMIFS(_dados_padronizados!E:E,_dados_padronizados!$A:$A,"3.01.01.01.01.98*")+SUMIFS(_dados_padronizados!E:E,_dados_padronizados!$A:$A,"3.01.01.01.01.08*")+SUMIFS(_dados_padronizados!E:E,_dados_padronizados!$A:$A,"3.01.01.01.01.20*"),0) | G11: =IFERROR(SUMIFS(_dados_padronizados!F:F,_dados_padronizados!$A:$A,"3.01.01.01.01.98*")+SUMIFS(_dados_padronizados!F:F,_dados_padronizados!$A:$A,"3.01.01.01.01.08*")+SUMIFS(_dados_padronizados!F:F,_dados_padronizados!$A:$A,"3.01.01.01.01.20*"),0) | H11: =IFERROR(SUMIFS(_dados_padronizados!G:G,_dados_padronizados!$A:$A,"3.01.01.01.01.98*")+SUMIFS(_dados_padronizados!G:G,_dados_padronizados!$A:$A,"3.01.01.01.01.08*")+SUMIFS(_dados_padronizados!G:G,_dados_padronizados!$A:$A,"3.01.01.01.01.20*"),0) | J11: =H11+I11
B12: (=) Receita bruta total | D12: =SUM(D9:D11) | E12: =SUM(E9:E11) | F12: =SUM(F9:F11) | G12: =SUM(G9:G11) | H12: =SUM(H9:H11) | I12: =SUM(I9:I11) | J12: =H12+I12
B14: DEDUÇÕES DA RECEITA BRUTA
B15: (-) Tributos sobre vendas e serviços | C15: 3.01.01.01.02.03|3.01.01.01.02.04|3.01.01.01.02.05|3.01.01.01.02.06|3.01.01.01.02.09 | D15: =IFERROR(SUMIFS(_dados_padronizados!C:C,_dados_padronizados!$A:$A,"3.01.01.01.02.03*")+SUMIFS(_dados_padronizados!C:C,_dados_padronizados!$A:$A,"3.01.01.01.02.04*")+SUMIFS(_dados_padronizados!C:C,_dados_padronizados!$A:$A,"3.01.01.01.02.05*")+SUMIFS(_dados_padronizados!C:C,_dados_padronizados!$A:$A,"3.01.01.01.02.06*")+SUMIFS(_dados_padronizados!C:C,_dados_padronizados!$A:$A,"3.01.01.01.02.09*"),0) | E15: =IFERROR(SUMIFS(_dados_padronizados!D:D,_dados_padronizados!$A:$A,"3.01.01.01.02.03*")+SUMIFS(_dados_padronizados!D:D,_dados_padronizados!$A:$A,"3.01.01.01.02.04*")+SUMIFS(_dados_padronizados!D:D,_dados_padronizados!$A:$A,"3.01.01.01.02.05*")+SUMIFS(_dados_padronizados!D:D,_dados_padronizados!$A:$A,"3.01.01.01.02.06*")+SUMIFS(_dados_padronizados!D:D,_dados_padronizados!$A:$A,"3.01.01.01.02.09*"),0) | F15: =IFERROR(SUMIFS(_dados_padronizados!E:E,_dados_padronizados!$A:$A,"3.01.01.01.02.03*")+SUMIFS(_dados_padronizados!E:E,_dados_padronizados!$A:$A,"3.01.01.01.02.04*")+SUMIFS(_dados_padronizados!E:E,_dados_padronizados!$A:$A,"3.01.01.01.02.05*")+SUMIFS(_dados_padronizados!E:E,_dados_padronizados!$A:$A,"3.01.01.01.02.06*")+SUMIFS(_dados_padronizados!E:E,_dados_padronizados!$A:$A,"3.01.01.01.02.09*"),0) | G15: =IFERROR(SUMIFS(_dados_padronizados!F:F,_dados_padronizados!$A:$A,"3.01.01.01.02.03*")+SUMIFS(_dados_padronizados!F:F,_dados_padronizados!$A:$A,"3.01.01.01.02.04*")+SUMIFS(_dados_padronizados!F:F,_dados_padronizados!$A:$A,"3.01.01.01.02.05*")+SUMIFS(_dados_padronizados!F:F,_dados_padronizados!$A:$A,"3.01.01.01.02.06*")+SUMIFS(_dados_padronizados!F:F,_dados_padronizados!$A:$A,"3.01.01.01.02.09*"),0) | H15: =IFERROR(SUMIFS(_dados_padronizados!G:G,_dados_padronizados!$A:$A,"3.01.01.01.02.03*")+SUMIFS(_dados_padronizados!G:G,_dados_padronizados!$A:$A,"3.01.01.01.02.04*")+SUMIFS(_dados_padronizados!G:G,_dados_padronizados!$A:$A,"3.01.01.01.02.05*")+SUMIFS(_dados_padronizados!G:G,_dados_padronizados!$A:$A,"3.01.01.01.02.06*")+SUMIFS(_dados_padronizados!G:G,_dados_padronizados!$A:$A,"3.01.01.01.02.09*"),0) | J15: =H15+I15
B16: (-) Devoluções, abatimentos e descontos | C16: 3.01.01.01.02.01|3.01.01.01.02.02 | D16: =IFERROR(SUMIFS(_dados_padronizados!C:C,_dados_padronizados!$A:$A,"3.01.01.01.02.01*")+SUMIFS(_dados_padronizados!C:C,_dados_padronizados!$A:$A,"3.01.01.01.02.02*"),0) | E16: =IFERROR(SUMIFS(_dados_padronizados!D:D,_dados_padronizados!$A:$A,"3.01.01.01.02.01*")+SUMIFS(_dados_padronizados!D:D,_dados_padronizados!$A:$A,"3.01.01.01.02.02*"),0) | F16: =IFERROR(SUMIFS(_dados_padronizados!E:E,_dados_padronizados!$A:$A,"3.01.01.01.02.01*")+SUMIFS(_dados_padronizados!E:E,_dados_padronizados!$A:$A,"3.01.01.01.02.02*"),0) | G16: =IFERROR(SUMIFS(_dados_padronizados!F:F,_dados_padronizados!$A:$A,"3.01.01.01.02.01*")+SUMIFS(_dados_padronizados!F:F,_dados_padronizados!$A:$A,"3.01.01.01.02.02*"),0) | H16: =IFERROR(SUMIFS(_dados_padronizados!G:G,_dados_padronizados!$A:$A,"3.01.01.01.02.01*")+SUMIFS(_dados_padronizados!G:G,_dados_padronizados!$A:$A,"3.01.01.01.02.02*"),0) | J16: =H16+I16
B17: (=) Total das deduções | D17: =SUM(D15:D16) | E17: =SUM(E15:E16) | F17: =SUM(F15:F16) | G17: =SUM(G15:G16) | H17: =SUM(H15:H16) | I17: =SUM(I15:I16) | J17: =H17+I17
B19: (=) RECEITA OPERACIONAL LÍQUIDA | D19: =D12+D17 | E19: =E12+E17 | F19: =F12+F17 | G19: =G12+G17 | H19: =H12+H17 | I19: =I12+I17 | J19: =H19+I19
B21: (-) Custos dos produtos, mercadorias e serviços vendidos | C21: 3.01.01.03 | D21: =IFERROR(SUMIFS(_dados_padronizados!C:C,_dados_padronizados!$A:$A,$C21&"*"),0) | E21: =IFERROR(SUMIFS(_dados_padronizados!D:D,_dados_padronizados!$A:$A,$C21&"*"),0) | F21: =IFERROR(SUMIFS(_dados_padronizados!E:E,_dados_padronizados!$A:$A,$C21&"*"),0) | G21: =IFERROR(SUMIFS(_dados_padronizados!F:F,_dados_padronizados!$A:$A,$C21&"*"),0) | H21: =IFERROR(SUMIFS(_dados_padronizados!G:G,_dados_padronizados!$A:$A,$C21&"*"),0) | J21: =H21+I21
B22: (=) LUCRO BRUTO | D22: =D19+D21 | E22: =E19+E21 | F22: =F19+F21 | G22: =G19+G21 | H22: =H19+H21 | I22: =I19+I21 | J22: =H22+I22
B24: DESPESAS OPERACIONAIS
B25: (-) Despesas com vendas | C25: 3.01.01.07.01.20|3.01.01.07.01.21 | D25: =IFERROR(SUMIFS(_dados_padronizados!C:C,_dados_padronizados!$A:$A,"3.01.01.07.01.20*")+SUMIFS(_dados_padronizados!C:C,_dados_padronizados!$A:$A,"3.01.01.07.01.21*"),0) | E25: =IFERROR(SUMIFS(_dados_padronizados!D:D,_dados_padronizados!$A:$A,"3.01.01.07.01.20*")+SUMIFS(_dados_padronizados!D:D,_dados_padronizados!$A:$A,"3.01.01.07.01.21*"),0) | F25: =IFERROR(SUMIFS(_dados_padronizados!E:E,_dados_padronizados!$A:$A,"3.01.01.07.01.20*")+SUMIFS(_dados_padronizados!E:E,_dados_padronizados!$A:$A,"3.01.01.07.01.21*"),0) | G25: =IFERROR(SUMIFS(_dados_padronizados!F:F,_dados_padronizados!$A:$A,"3.01.01.07.01.20*")+SUMIFS(_dados_padronizados!F:F,_dados_padronizados!$A:$A,"3.01.01.07.01.21*"),0) | H25: =IFERROR(SUMIFS(_dados_padronizados!G:G,_dados_padronizados!$A:$A,"3.01.01.07.01.20*")+SUMIFS(_dados_padronizados!G:G,_dados_padronizados!$A:$A,"3.01.01.07.01.21*"),0) | J25: =H25+I25
B26: (-) Despesas com pessoal | C26: 3.01.01.07.01.01|3.01.01.07.01.02|3.01.01.07.01.03|3.01.01.07.01.05|3.01.01.07.01.06|3.01.01.07.01.07|3.01.01.07.01.30|3.01.01.07.01.33 | D26: =IFERROR(SUMIFS(_dados_padronizados!C:C,_dados_padronizados!$A:$A,"3.01.01.07.01.01*")+SUMIFS(_dados_padronizados!C:C,_dados_padronizados!$A:$A,"3.01.01.07.01.02*")+SUMIFS(_dados_padronizados!C:C,_dados_padronizados!$A:$A,"3.01.01.07.01.03*")+SUMIFS(_dados_padronizados!C:C,_dados_padronizados!$A:$A,"3.01.01.07.01.05*")+SUMIFS(_dados_padronizados!C:C,_dados_padronizados!$A:$A,"3.01.01.07.01.06*")+SUMIFS(_dados_padronizados!C:C,_dados_padronizados!$A:$A,"3.01.01.07.01.07*")+SUMIFS(_dados_padronizados!C:C,_dados_padronizados!$A:$A,"3.01.01.07.01.30*")+SUMIFS(_dados_padronizados!C:C,_dados_padronizados!$A:$A,"3.01.01.07.01.33*"),0) | E26: =IFERROR(SUMIFS(_dados_padronizados!D:D,_dados_padronizados!$A:$A,"3.01.01.07.01.01*")+SUMIFS(_dados_padronizados!D:D,_dados_padronizados!$A:$A,"3.01.01.07.01.02*")+SUMIFS(_dados_padronizados!D:D,_dados_padronizados!$A:$A,"3.01.01.07.01.03*")+SUMIFS(_dados_padronizados!D:D,_dados_padronizados!$A:$A,"3.01.01.07.01.05*")+SUMIFS(_dados_padronizados!D:D,_dados_padronizados!$A:$A,"3.01.01.07.01.06*")+SUMIFS(_dados_padronizados!D:D,_dados_padronizados!$A:$A,"3.01.01.07.01.07*")+SUMIFS(_dados_padronizados!D:D,_dados_padronizados!$A:$A,"3.01.01.07.01.30*")+SUMIFS(_dados_padronizados!D:D,_dados_padronizados!$A:$A,"3.01.01.07.01.33*"),0) | F26: =IFERROR(SUMIFS(_dados_padronizados!E:E,_dados_padronizados!$A:$A,"3.01.01.07.01.01*")+SUMIFS(_dados_padronizados!E:E,_dados_padronizados!$A:$A,"3.01.01.07.01.02*")+SUMIFS(_dados_padronizados!E:E,_dados_padronizados!$A:$A,"3.01.01.07.01.03*")+SUMIFS(_dados_padronizados!E:E,_dados_padronizados!$A:$A,"3.01.01.07.01.05*")+SUMIFS(_dados_padronizados!E:E,_dados_padronizados!$A:$A,"3.01.01.07.01.06*")+SUMIFS(_dados_padronizados!E:E,_dados_padronizados!$A:$A,"3.01.01.07.01.07*")+SUMIFS(_dados_padronizados!E:E,_dados_padronizados!$A:$A,"3.01.01.07.01.30*")+SUMIFS(_dados_padronizados!E:E,_dados_padronizados!$A:$A,"3.01.01.07.01.33*"),0) | G26: =IFERROR(SUMIFS(_dados_padronizados!F:F,_dados_padronizados!$A:$A,"3.01.01.07.01.01*")+SUMIFS(_dados_padronizados!F:F,_dados_padronizados!$A:$A,"3.01.01.07.01.02*")+SUMIFS(_dados_padronizados!F:F,_dados_padronizados!$A:$A,"3.01.01.07.01.03*")+SUMIFS(_dados_padronizados!F:F,_dados_padronizados!$A:$A,"3.01.01.07.01.05*")+SUMIFS(_dados_padronizados!F:F,_dados_padronizados!$A:$A,"3.01.01.07.01.06*")+SUMIFS(_dados_padronizados!F:F,_dados_padronizados!$A:$A,"3.01.01.07.01.07*")+SUMIFS(_dados_padronizados!F:F,_dados_padronizados!$A:$A,"3.01.01.07.01.30*")+SUMIFS(_dados_padronizados!F:F,_dados_padronizados!$A:$A,"3.01.01.07.01.33*"),0) | H26: =IFERROR(SUMIFS(_dados_padronizados!G:G,_dados_padronizados!$A:$A,"3.01.01.07.01.01*")+SUMIFS(_dados_padronizados!G:G,_dados_padronizados!$A:$A,"3.01.01.07.01.02*")+SUMIFS(_dados_padronizados!G:G,_dados_padronizados!$A:$A,"3.01.01.07.01.03*")+SUMIFS(_dados_padronizados!G:G,_dados_padronizados!$A:$A,"3.01.01.07.01.05*")+SUMIFS(_dados_padronizados!G:G,_dados_padronizados!$A:$A,"3.01.01.07.01.06*")+SUMIFS(_dados_padronizados!G:G,_dados_padronizados!$A:$A,"3.01.01.07.01.07*")+SUMIFS(_dados_padronizados!G:G,_dados_padronizados!$A:$A,"3.01.01.07.01.30*")+SUMIFS(_dados_padronizados!G:G,_dados_padronizados!$A:$A,"3.01.01.07.01.33*"),0) | J26: =H26+I26
B27: (-) Despesas gerais e administrativas | C27: 3.01.01.07.01.04|3.01.01.07.01.17|3.01.01.07.01.18|3.01.01.07.01.19|3.01.01.07.01.36|3.01.01.07.01.37|3.01.01.07.01.38|3.01.01.07.01.40 | D27: =IFERROR(SUMIFS(_dados_padronizados!C:C,_dados_padronizados!$A:$A,"3.01.01.07.01.04*")+SUMIFS(_dados_padronizados!C:C,_dados_padronizados!$A:$A,"3.01.01.07.01.17*")+SUMIFS(_dados_padronizados!C:C,_dados_padronizados!$A:$A,"3.01.01.07.01.18*")+SUMIFS(_dados_padronizados!C:C,_dados_padronizados!$A:$A,"3.01.01.07.01.19*")+SUMIFS(_dados_padronizados!C:C,_dados_padronizados!$A:$A,"3.01.01.07.01.36*")+SUMIFS(_dados_padronizados!C:C,_dados_padronizados!$A:$A,"3.01.01.07.01.37*")+SUMIFS(_dados_padronizados!C:C,_dados_padronizados!$A:$A,"3.01.01.07.01.38*")+SUMIFS(_dados_padronizados!C:C,_dados_padronizados!$A:$A,"3.01.01.07.01.40*"),0) | E27: =IFERROR(SUMIFS(_dados_padronizados!D:D,_dados_padronizados!$A:$A,"3.01.01.07.01.04*")+SUMIFS(_dados_padronizados!D:D,_dados_padronizados!$A:$A,"3.01.01.07.01.17*")+SUMIFS(_dados_padronizados!D:D,_dados_padronizados!$A:$A,"3.01.01.07.01.18*")+SUMIFS(_dados_padronizados!D:D,_dados_padronizados!$A:$A,"3.01.01.07.01.19*")+SUMIFS(_dados_padronizados!D:D,_dados_padronizados!$A:$A,"3.01.01.07.01.36*")+SUMIFS(_dados_padronizados!D:D,_dados_padronizados!$A:$A,"3.01.01.07.01.37*")+SUMIFS(_dados_padronizados!D:D,_dados_padronizados!$A:$A,"3.01.01.07.01.38*")+SUMIFS(_dados_padronizados!D:D,_dados_padronizados!$A:$A,"3.01.01.07.01.40*"),0) | F27: =IFERROR(SUMIFS(_dados_padronizados!E:E,_dados_padronizados!$A:$A,"3.01.01.07.01.04*")+SUMIFS(_dados_padronizados!E:E,_dados_padronizados!$A:$A,"3.01.01.07.01.17*")+SUMIFS(_dados_padronizados!E:E,_dados_padronizados!$A:$A,"3.01.01.07.01.18*")+SUMIFS(_dados_padronizados!E:E,_dados_padronizados!$A:$A,"3.01.01.07.01.19*")+SUMIFS(_dados_padronizados!E:E,_dados_padronizados!$A:$A,"3.01.01.07.01.36*")+SUMIFS(_dados_padronizados!E:E,_dados_padronizados!$A:$A,"3.01.01.07.01.37*")+SUMIFS(_dados_padronizados!E:E,_dados_padronizados!$A:$A,"3.01.01.07.01.38*")+SUMIFS(_dados_padronizados!E:E,_dados_padronizados!$A:$A,"3.01.01.07.01.40*"),0) | G27: =IFERROR(SUMIFS(_dados_padronizados!F:F,_dados_padronizados!$A:$A,"3.01.01.07.01.04*")+SUMIFS(_dados_padronizados!F:F,_dados_padronizados!$A:$A,"3.01.01.07.01.17*")+SUMIFS(_dados_padronizados!F:F,_dados_padronizados!$A:$A,"3.01.01.07.01.18*")+SUMIFS(_dados_padronizados!F:F,_dados_padronizados!$A:$A,"3.01.01.07.01.19*")+SUMIFS(_dados_padronizados!F:F,_dados_padronizados!$A:$A,"3.01.01.07.01.36*")+SUMIFS(_dados_padronizados!F:F,_dados_padronizados!$A:$A,"3.01.01.07.01.37*")+SUMIFS(_dados_padronizados!F:F,_dados_padronizados!$A:$A,"3.01.01.07.01.38*")+SUMIFS(_dados_padronizados!F:F,_dados_padronizados!$A:$A,"3.01.01.07.01.40*"),0) | H27: =IFERROR(SUMIFS(_dados_padronizados!G:G,_dados_padronizados!$A:$A,"3.01.01.07.01.04*")+SUMIFS(_dados_padronizados!G:G,_dados_padronizados!$A:$A,"3.01.01.07.01.17*")+SUMIFS(_dados_padronizados!G:G,_dados_padronizados!$A:$A,"3.01.01.07.01.18*")+SUMIFS(_dados_padronizados!G:G,_dados_padronizados!$A:$A,"3.01.01.07.01.19*")+SUMIFS(_dados_padronizados!G:G,_dados_padronizados!$A:$A,"3.01.01.07.01.36*")+SUMIFS(_dados_padronizados!G:G,_dados_padronizados!$A:$A,"3.01.01.07.01.37*")+SUMIFS(_dados_padronizados!G:G,_dados_padronizados!$A:$A,"3.01.01.07.01.38*")+SUMIFS(_dados_padronizados!G:G,_dados_padronizados!$A:$A,"3.01.01.07.01.40*"),0) | J27: =H27+I27
B28: (+) Outras receitas operacionais | C28: 3.01.01.05.01.10|3.01.01.05.01.99 | D28: =IFERROR(SUMIFS(_dados_padronizados!C:C,_dados_padronizados!$A:$A,"3.01.01.05.01.10*")+SUMIFS(_dados_padronizados!C:C,_dados_padronizados!$A:$A,"3.01.01.05.01.99*"),0) | E28: =IFERROR(SUMIFS(_dados_padronizados!D:D,_dados_padronizados!$A:$A,"3.01.01.05.01.10*")+SUMIFS(_dados_padronizados!D:D,_dados_padronizados!$A:$A,"3.01.01.05.01.99*"),0) | F28: =IFERROR(SUMIFS(_dados_padronizados!E:E,_dados_padronizados!$A:$A,"3.01.01.05.01.10*")+SUMIFS(_dados_padronizados!E:E,_dados_padronizados!$A:$A,"3.01.01.05.01.99*"),0) | G28: =IFERROR(SUMIFS(_dados_padronizados!F:F,_dados_padronizados!$A:$A,"3.01.01.05.01.10*")+SUMIFS(_dados_padronizados!F:F,_dados_padronizados!$A:$A,"3.01.01.05.01.99*"),0) | H28: =IFERROR(SUMIFS(_dados_padronizados!G:G,_dados_padronizados!$A:$A,"3.01.01.05.01.10*")+SUMIFS(_dados_padronizados!G:G,_dados_padronizados!$A:$A,"3.01.01.05.01.99*"),0) | J28: =H28+I28
B29: (-) Outras despesas operacionais | C29: 3.01.01.07.01.14|3.01.01.07.01.15|3.01.01.07.01.16|3.01.01.07.01.22|3.01.01.09.01.99 | D29: =IFERROR(SUMIFS(_dados_padronizados!C:C,_dados_padronizados!$A:$A,"3.01.01.07.01.14*")+SUMIFS(_dados_padronizados!C:C,_dados_padronizados!$A:$A,"3.01.01.07.01.15*")+SUMIFS(_dados_padronizados!C:C,_dados_padronizados!$A:$A,"3.01.01.07.01.16*")+SUMIFS(_dados_padronizados!C:C,_dados_padronizados!$A:$A,"3.01.01.07.01.22*")+SUMIFS(_dados_padronizados!C:C,_dados_padronizados!$A:$A,"3.01.01.09.01.99*"),0) | E29: =IFERROR(SUMIFS(_dados_padronizados!D:D,_dados_padronizados!$A:$A,"3.01.01.07.01.14*")+SUMIFS(_dados_padronizados!D:D,_dados_padronizados!$A:$A,"3.01.01.07.01.15*")+SUMIFS(_dados_padronizados!D:D,_dados_padronizados!$A:$A,"3.01.01.07.01.16*")+SUMIFS(_dados_padronizados!D:D,_dados_padronizados!$A:$A,"3.01.01.07.01.22*")+SUMIFS(_dados_padronizados!D:D,_dados_padronizados!$A:$A,"3.01.01.09.01.99*"),0) | F29: =IFERROR(SUMIFS(_dados_padronizados!E:E,_dados_padronizados!$A:$A,"3.01.01.07.01.14*")+SUMIFS(_dados_padronizados!E:E,_dados_padronizados!$A:$A,"3.01.01.07.01.15*")+SUMIFS(_dados_padronizados!E:E,_dados_padronizados!$A:$A,"3.01.01.07.01.16*")+SUMIFS(_dados_padronizados!E:E,_dados_padronizados!$A:$A,"3.01.01.07.01.22*")+SUMIFS(_dados_padronizados!E:E,_dados_padronizados!$A:$A,"3.01.01.09.01.99*"),0) | G29: =IFERROR(SUMIFS(_dados_padronizados!F:F,_dados_padronizados!$A:$A,"3.01.01.07.01.14*")+SUMIFS(_dados_padronizados!F:F,_dados_padronizados!$A:$A,"3.01.01.07.01.15*")+SUMIFS(_dados_padronizados!F:F,_dados_padronizados!$A:$A,"3.01.01.07.01.16*")+SUMIFS(_dados_padronizados!F:F,_dados_padronizados!$A:$A,"3.01.01.07.01.22*")+SUMIFS(_dados_padronizados!F:F,_dados_padronizados!$A:$A,"3.01.01.09.01.99*"),0) | H29: =IFERROR(SUMIFS(_dados_padronizados!G:G,_dados_padronizados!$A:$A,"3.01.01.07.01.14*")+SUMIFS(_dados_padronizados!G:G,_dados_padronizados!$A:$A,"3.01.01.07.01.15*")+SUMIFS(_dados_padronizados!G:G,_dados_padronizados!$A:$A,"3.01.01.07.01.16*")+SUMIFS(_dados_padronizados!G:G,_dados_padronizados!$A:$A,"3.01.01.07.01.22*")+SUMIFS(_dados_padronizados!G:G,_dados_padronizados!$A:$A,"3.01.01.09.01.99*"),0) | J29: =H29+I29
B31: (=) EBITDA | D31: =D22+SUM(D25:D30) | E31: =E22+SUM(E25:E30) | F31: =F22+SUM(F25:F30) | G31: =G22+SUM(G25:G30) | H31: =H22+SUM(H25:H30) | I31: =I22+SUM(I25:I30) | J31: =H31+I31
B33: (-) Depreciação e amortização | C33: 3.01.01.07.01.23|3.01.01.07.01.24 | D33: =IFERROR(SUMIFS(_dados_padronizados!C:C,_dados_padronizados!$A:$A,"3.01.01.07.01.23*")+SUMIFS(_dados_padronizados!C:C,_dados_padronizados!$A:$A,"3.01.01.07.01.24*"),0) | E33: =IFERROR(SUMIFS(_dados_padronizados!D:D,_dados_padronizados!$A:$A,"3.01.01.07.01.23*")+SUMIFS(_dados_padronizados!D:D,_dados_padronizados!$A:$A,"3.01.01.07.01.24*"),0) | F33: =IFERROR(SUMIFS(_dados_padronizados!E:E,_dados_padronizados!$A:$A,"3.01.01.07.01.23*")+SUMIFS(_dados_padronizados!E:E,_dados_padronizados!$A:$A,"3.01.01.07.01.24*"),0) | G33: =IFERROR(SUMIFS(_dados_padronizados!F:F,_dados_padronizados!$A:$A,"3.01.01.07.01.23*")+SUMIFS(_dados_padronizados!F:F,_dados_padronizados!$A:$A,"3.01.01.07.01.24*"),0) | H33: =IFERROR(SUMIFS(_dados_padronizados!G:G,_dados_padronizados!$A:$A,"3.01.01.07.01.23*")+SUMIFS(_dados_padronizados!G:G,_dados_padronizados!$A:$A,"3.01.01.07.01.24*"),0) | J33: =H33+I33
B34: (=) EBIT | D34: =D31+D33 | E34: =E31+E33 | F34: =F31+F33 | G34: =G31+G33 | H34: =H31+H33 | I34: =I31+I33 | J34: =H34+I34
B36: RESULTADO FINANCEIRO
B37: (+) Receitas financeiras | C37: 3.01.01.05.01.01|3.01.01.05.01.04|3.01.01.05.01.05|3.01.01.05.01.31|3.01.01.05.01.32 | D37: =IFERROR(SUMIFS(_dados_padronizados!C:C,_dados_padronizados!$A:$A,"3.01.01.05.01.01*")+SUMIFS(_dados_padronizados!C:C,_dados_padronizados!$A:$A,"3.01.01.05.01.04*")+SUMIFS(_dados_padronizados!C:C,_dados_padronizados!$A:$A,"3.01.01.05.01.05*")+SUMIFS(_dados_padronizados!C:C,_dados_padronizados!$A:$A,"3.01.01.05.01.31*")+SUMIFS(_dados_padronizados!C:C,_dados_padronizados!$A:$A,"3.01.01.05.01.32*"),0) | E37: =IFERROR(SUMIFS(_dados_padronizados!D:D,_dados_padronizados!$A:$A,"3.01.01.05.01.01*")+SUMIFS(_dados_padronizados!D:D,_dados_padronizados!$A:$A,"3.01.01.05.01.04*")+SUMIFS(_dados_padronizados!D:D,_dados_padronizados!$A:$A,"3.01.01.05.01.05*")+SUMIFS(_dados_padronizados!D:D,_dados_padronizados!$A:$A,"3.01.01.05.01.31*")+SUMIFS(_dados_padronizados!D:D,_dados_padronizados!$A:$A,"3.01.01.05.01.32*"),0) | F37: =IFERROR(SUMIFS(_dados_padronizados!E:E,_dados_padronizados!$A:$A,"3.01.01.05.01.01*")+SUMIFS(_dados_padronizados!E:E,_dados_padronizados!$A:$A,"3.01.01.05.01.04*")+SUMIFS(_dados_padronizados!E:E,_dados_padronizados!$A:$A,"3.01.01.05.01.05*")+SUMIFS(_dados_padronizados!E:E,_dados_padronizados!$A:$A,"3.01.01.05.01.31*")+SUMIFS(_dados_padronizados!E:E,_dados_padronizados!$A:$A,"3.01.01.05.01.32*"),0) | G37: =IFERROR(SUMIFS(_dados_padronizados!F:F,_dados_padronizados!$A:$A,"3.01.01.05.01.01*")+SUMIFS(_dados_padronizados!F:F,_dados_padronizados!$A:$A,"3.01.01.05.01.04*")+SUMIFS(_dados_padronizados!F:F,_dados_padronizados!$A:$A,"3.01.01.05.01.05*")+SUMIFS(_dados_padronizados!F:F,_dados_padronizados!$A:$A,"3.01.01.05.01.31*")+SUMIFS(_dados_padronizados!F:F,_dados_padronizados!$A:$A,"3.01.01.05.01.32*"),0) | H37: =IFERROR(SUMIFS(_dados_padronizados!G:G,_dados_padronizados!$A:$A,"3.01.01.05.01.01*")+SUMIFS(_dados_padronizados!G:G,_dados_padronizados!$A:$A,"3.01.01.05.01.04*")+SUMIFS(_dados_padronizados!G:G,_dados_padronizados!$A:$A,"3.01.01.05.01.05*")+SUMIFS(_dados_padronizados!G:G,_dados_padronizados!$A:$A,"3.01.01.05.01.31*")+SUMIFS(_dados_padronizados!G:G,_dados_padronizados!$A:$A,"3.01.01.05.01.32*"),0) | J37: =H37+I37
B38: (-) Despesas financeiras | C38: 3.01.01.09.01.01|3.01.01.09.01.04|3.01.01.09.01.05|3.01.01.09.01.06|3.01.01.09.01.07|3.01.01.09.01.08|3.01.01.09.01.15 | D38: =IFERROR(SUMIFS(_dados_padronizados!C:C,_dados_padronizados!$A:$A,"3.01.01.09.01.01*")+SUMIFS(_dados_padronizados!C:C,_dados_padronizados!$A:$A,"3.01.01.09.01.04*")+SUMIFS(_dados_padronizados!C:C,_dados_padronizados!$A:$A,"3.01.01.09.01.05*")+SUMIFS(_dados_padronizados!C:C,_dados_padronizados!$A:$A,"3.01.01.09.01.06*")+SUMIFS(_dados_padronizados!C:C,_dados_padronizados!$A:$A,"3.01.01.09.01.07*")+SUMIFS(_dados_padronizados!C:C,_dados_padronizados!$A:$A,"3.01.01.09.01.08*")+SUMIFS(_dados_padronizados!C:C,_dados_padronizados!$A:$A,"3.01.01.09.01.15*"),0) | E38: =IFERROR(SUMIFS(_dados_padronizados!D:D,_dados_padronizados!$A:$A,"3.01.01.09.01.01*")+SUMIFS(_dados_padronizados!D:D,_dados_padronizados!$A:$A,"3.01.01.09.01.04*")+SUMIFS(_dados_padronizados!D:D,_dados_padronizados!$A:$A,"3.01.01.09.01.05*")+SUMIFS(_dados_padronizados!D:D,_dados_padronizados!$A:$A,"3.01.01.09.01.06*")+SUMIFS(_dados_padronizados!D:D,_dados_padronizados!$A:$A,"3.01.01.09.01.07*")+SUMIFS(_dados_padronizados!D:D,_dados_padronizados!$A:$A,"3.01.01.09.01.08*")+SUMIFS(_dados_padronizados!D:D,_dados_padronizados!$A:$A,"3.01.01.09.01.15*"),0) | F38: =IFERROR(SUMIFS(_dados_padronizados!E:E,_dados_padronizados!$A:$A,"3.01.01.09.01.01*")+SUMIFS(_dados_padronizados!E:E,_dados_padronizados!$A:$A,"3.01.01.09.01.04*")+SUMIFS(_dados_padronizados!E:E,_dados_padronizados!$A:$A,"3.01.01.09.01.05*")+SUMIFS(_dados_padronizados!E:E,_dados_padronizados!$A:$A,"3.01.01.09.01.06*")+SUMIFS(_dados_padronizados!E:E,_dados_padronizados!$A:$A,"3.01.01.09.01.07*")+SUMIFS(_dados_padronizados!E:E,_dados_padronizados!$A:$A,"3.01.01.09.01.08*")+SUMIFS(_dados_padronizados!E:E,_dados_padronizados!$A:$A,"3.01.01.09.01.15*"),0) | G38: =IFERROR(SUMIFS(_dados_padronizados!F:F,_dados_padronizados!$A:$A,"3.01.01.09.01.01*")+SUMIFS(_dados_padronizados!F:F,_dados_padronizados!$A:$A,"3.01.01.09.01.04*")+SUMIFS(_dados_padronizados!F:F,_dados_padronizados!$A:$A,"3.01.01.09.01.05*")+SUMIFS(_dados_padronizados!F:F,_dados_padronizados!$A:$A,"3.01.01.09.01.06*")+SUMIFS(_dados_padronizados!F:F,_dados_padronizados!$A:$A,"3.01.01.09.01.07*")+SUMIFS(_dados_padronizados!F:F,_dados_padronizados!$A:$A,"3.01.01.09.01.08*")+SUMIFS(_dados_padronizados!F:F,_dados_padronizados!$A:$A,"3.01.01.09.01.15*"),0) | H38: =IFERROR(SUMIFS(_dados_padronizados!G:G,_dados_padronizados!$A:$A,"3.01.01.09.01.01*")+SUMIFS(_dados_padronizados!G:G,_dados_padronizados!$A:$A,"3.01.01.09.01.04*")+SUMIFS(_dados_padronizados!G:G,_dados_padronizados!$A:$A,"3.01.01.09.01.05*")+SUMIFS(_dados_padronizados!G:G,_dados_padronizados!$A:$A,"3.01.01.09.01.06*")+SUMIFS(_dados_padronizados!G:G,_dados_padronizados!$A:$A,"3.01.01.09.01.07*")+SUMIFS(_dados_padronizados!G:G,_dados_padronizados!$A:$A,"3.01.01.09.01.08*")+SUMIFS(_dados_padronizados!G:G,_dados_padronizados!$A:$A,"3.01.01.09.01.15*"),0) | J38: =H38+I38
B39: (=) Resultado financeiro líquido | D39: =SUM(D37:D38) | E39: =SUM(E37:E38) | F39: =SUM(F37:F38) | G39: =SUM(G37:G38) | H39: =SUM(H37:H38) | I39: =SUM(I37:I38) | J39: =H39+I39
B41: (+/-) Resultado de equivalência patrimonial | C41: 3.01.01.05.01.06|3.01.01.05.01.07|3.01.01.09.01.09|3.01.01.09.01.10 | D41: =IFERROR(SUMIFS(_dados_padronizados!C:C,_dados_padronizados!$A:$A,"3.01.01.05.01.06*")+SUMIFS(_dados_padronizados!C:C,_dados_padronizados!$A:$A,"3.01.01.05.01.07*")+SUMIFS(_dados_padronizados!C:C,_dados_padronizados!$A:$A,"3.01.01.09.01.09*")+SUMIFS(_dados_padronizados!C:C,_dados_padronizados!$A:$A,"3.01.01.09.01.10*"),0) | E41: =IFERROR(SUMIFS(_dados_padronizados!D:D,_dados_padronizados!$A:$A,"3.01.01.05.01.06*")+SUMIFS(_dados_padronizados!D:D,_dados_padronizados!$A:$A,"3.01.01.05.01.07*")+SUMIFS(_dados_padronizados!D:D,_dados_padronizados!$A:$A,"3.01.01.09.01.09*")+SUMIFS(_dados_padronizados!D:D,_dados_padronizados!$A:$A,"3.01.01.09.01.10*"),0) | F41: =IFERROR(SUMIFS(_dados_padronizados!E:E,_dados_padronizados!$A:$A,"3.01.01.05.01.06*")+SUMIFS(_dados_padronizados!E:E,_dados_padronizados!$A:$A,"3.01.01.05.01.07*")+SUMIFS(_dados_padronizados!E:E,_dados_padronizados!$A:$A,"3.01.01.09.01.09*")+SUMIFS(_dados_padronizados!E:E,_dados_padronizados!$A:$A,"3.01.01.09.01.10*"),0) | G41: =IFERROR(SUMIFS(_dados_padronizados!F:F,_dados_padronizados!$A:$A,"3.01.01.05.01.06*")+SUMIFS(_dados_padronizados!F:F,_dados_padronizados!$A:$A,"3.01.01.05.01.07*")+SUMIFS(_dados_padronizados!F:F,_dados_padronizados!$A:$A,"3.01.01.09.01.09*")+SUMIFS(_dados_padronizados!F:F,_dados_padronizados!$A:$A,"3.01.01.09.01.10*"),0) | H41: =IFERROR(SUMIFS(_dados_padronizados!G:G,_dados_padronizados!$A:$A,"3.01.01.05.01.06*")+SUMIFS(_dados_padronizados!G:G,_dados_padronizados!$A:$A,"3.01.01.05.01.07*")+SUMIFS(_dados_padronizados!G:G,_dados_padronizados!$A:$A,"3.01.01.09.01.09*")+SUMIFS(_dados_padronizados!G:G,_dados_padronizados!$A:$A,"3.01.01.09.01.10*"),0) | J41: =H41+I41
B43: (=) RESULTADO ANTES DO IRPJ/CSLL | D43: =D34+D39+D41 | E43: =E34+E39+E41 | F43: =F34+F39+F41 | G43: =G34+G39+G41 | H43: =H34+H39+H41 | I43: =I34+I39+I41 | J43: =H43+I43
B45: (-) IRPJ e CSLL correntes | C45: 3.02.01.01 | D45: =IFERROR(SUMIFS(_dados_padronizados!C:C,_dados_padronizados!$A:$A,$C45&"*"),0) | E45: =IFERROR(SUMIFS(_dados_padronizados!D:D,_dados_padronizados!$A:$A,$C45&"*"),0) | F45: =IFERROR(SUMIFS(_dados_padronizados!E:E,_dados_padronizados!$A:$A,$C45&"*"),0) | G45: =IFERROR(SUMIFS(_dados_padronizados!F:F,_dados_padronizados!$A:$A,$C45&"*"),0) | H45: =IFERROR(SUMIFS(_dados_padronizados!G:G,_dados_padronizados!$A:$A,$C45&"*"),0) | J45: =H45+I45
B46: (-) IRPJ e CSLL diferidos | C46: 3.02.01.02 | D46: =IFERROR(SUMIFS(_dados_padronizados!C:C,_dados_padronizados!$A:$A,$C46&"*"),0) | E46: =IFERROR(SUMIFS(_dados_padronizados!D:D,_dados_padronizados!$A:$A,$C46&"*"),0) | F46: =IFERROR(SUMIFS(_dados_padronizados!E:E,_dados_padronizados!$A:$A,$C46&"*"),0) | G46: =IFERROR(SUMIFS(_dados_padronizados!F:F,_dados_padronizados!$A:$A,$C46&"*"),0) | H46: =IFERROR(SUMIFS(_dados_padronizados!G:G,_dados_padronizados!$A:$A,$C46&"*"),0) | J46: =H46+I46
B48: (=) LUCRO LÍQUIDO DO EXERCÍCIO | D48: =D43+D45+D46 | E48: =E43+E45+E46 | F48: =F43+F45+F46 | G48: =G43+G45+G46 | H48: =H43+H45+H46 | I48: =I43+I45+I46 | J48: =H48+I48
B50: Check (Lucro líquido conforme cliente)

Sheet _dados_padronizados
A1: codigo_padronizado | B1: descricao_original | C1: 2021 | D1: 2022 | E1: 2023 | F1: 2024 | G1: 2025
